[2023-12-16T13:35:21.217+0000] {taskinstance.py:1159} INFO - Dependencies all met for dep_context=non-requeueable deps ti=<TaskInstance: NYC_Taxi_data_pipeline.integration scheduled__2023-12-14T00:00:00+00:00 [queued]>
[2023-12-16T13:35:21.225+0000] {taskinstance.py:1159} INFO - Dependencies all met for dep_context=requeueable deps ti=<TaskInstance: NYC_Taxi_data_pipeline.integration scheduled__2023-12-14T00:00:00+00:00 [queued]>
[2023-12-16T13:35:21.226+0000] {taskinstance.py:1361} INFO - Starting attempt 1 of 1
[2023-12-16T13:35:21.240+0000] {taskinstance.py:1382} INFO - Executing <Task(PythonOperator): integration> on 2023-12-14 00:00:00+00:00
[2023-12-16T13:35:21.245+0000] {standard_task_runner.py:57} INFO - Started process 329 to run task
[2023-12-16T13:35:21.248+0000] {standard_task_runner.py:84} INFO - Running: ['***', 'tasks', 'run', 'NYC_Taxi_data_pipeline', 'integration', 'scheduled__2023-12-14T00:00:00+00:00', '--job-id', '6', '--raw', '--subdir', 'DAGS_FOLDER/taxi_etl.py', '--cfg-path', '/tmp/tmpjkvzghtl']
[2023-12-16T13:35:21.251+0000] {standard_task_runner.py:85} INFO - Job 6: Subtask integration
[2023-12-16T13:35:21.332+0000] {task_command.py:416} INFO - Running <TaskInstance: NYC_Taxi_data_pipeline.integration scheduled__2023-12-14T00:00:00+00:00 [running]> on host 5325b8af6d98
[2023-12-16T13:35:21.413+0000] {taskinstance.py:1662} INFO - Exporting env vars: AIRFLOW_CTX_DAG_OWNER='islam' AIRFLOW_CTX_DAG_ID='NYC_Taxi_data_pipeline' AIRFLOW_CTX_TASK_ID='integration' AIRFLOW_CTX_EXECUTION_DATE='2023-12-14T00:00:00+00:00' AIRFLOW_CTX_TRY_NUMBER='1' AIRFLOW_CTX_DAG_RUN_ID='scheduled__2023-12-14T00:00:00+00:00'
[2023-12-16T13:35:22.661+0000] {logging_mixin.py:154} INFO - Database connect successfully
[2023-12-16T13:35:45.825+0000] {taskinstance.py:1937} ERROR - Task failed with exception
Traceback (most recent call last):
  File "/home/airflow/.local/lib/python3.8/site-packages/sqlalchemy/engine/base.py", line 1910, in _execute_context
    self.dialect.do_execute(
  File "/home/airflow/.local/lib/python3.8/site-packages/sqlalchemy/engine/default.py", line 736, in do_execute
    cursor.execute(statement, parameters)
psycopg2.errors.UniqueViolation: duplicate key value violates unique constraint "pg_type_typname_nsp_index"
DETAIL:  Key (typname, typnamespace)=(M4_green_taxis_11_2017, 2200) already exists.


The above exception was the direct cause of the following exception:

Traceback (most recent call last):
  File "/home/airflow/.local/lib/python3.8/site-packages/airflow/operators/python.py", line 192, in execute
    return_value = self.execute_callable()
  File "/home/airflow/.local/lib/python3.8/site-packages/airflow/operators/python.py", line 209, in execute_callable
    return self.python_callable(*self.op_args, **self.op_kwargs)
  File "/opt/airflow/dags/tasks.py", line 127, in integrate_and_load
    upload_csv(df_with_gps, "M4_green_taxis_11_2017", con)
  File "/opt/airflow/dags/utilities.py", line 40, in upload_csv
    df.to_sql(table_name, con = engine, if_exists='fail', index=False)
  File "/home/airflow/.local/lib/python3.8/site-packages/pandas/core/generic.py", line 2878, in to_sql
    return sql.to_sql(
  File "/home/airflow/.local/lib/python3.8/site-packages/pandas/io/sql.py", line 769, in to_sql
    return pandas_sql.to_sql(
  File "/home/airflow/.local/lib/python3.8/site-packages/pandas/io/sql.py", line 1910, in to_sql
    table = self.prep_table(
  File "/home/airflow/.local/lib/python3.8/site-packages/pandas/io/sql.py", line 1814, in prep_table
    table.create()
  File "/home/airflow/.local/lib/python3.8/site-packages/pandas/io/sql.py", line 914, in create
    self._execute_create()
  File "/home/airflow/.local/lib/python3.8/site-packages/pandas/io/sql.py", line 900, in _execute_create
    self.table.create(bind=self.pd_sql.con)
  File "/home/airflow/.local/lib/python3.8/site-packages/sqlalchemy/sql/schema.py", line 962, in create
    bind._run_ddl_visitor(ddl.SchemaGenerator, self, checkfirst=checkfirst)
  File "/home/airflow/.local/lib/python3.8/site-packages/sqlalchemy/engine/base.py", line 2221, in _run_ddl_visitor
    visitorcallable(self.dialect, self, **kwargs).traverse_single(element)
  File "/home/airflow/.local/lib/python3.8/site-packages/sqlalchemy/sql/visitors.py", line 524, in traverse_single
    return meth(obj, **kw)
  File "/home/airflow/.local/lib/python3.8/site-packages/sqlalchemy/sql/ddl.py", line 899, in visit_table
    self.connection.execute(
  File "/home/airflow/.local/lib/python3.8/site-packages/sqlalchemy/engine/base.py", line 1385, in execute
    return meth(self, multiparams, params, _EMPTY_EXECUTION_OPTS)
  File "/home/airflow/.local/lib/python3.8/site-packages/sqlalchemy/sql/ddl.py", line 80, in _execute_on_connection
    return connection._execute_ddl(
  File "/home/airflow/.local/lib/python3.8/site-packages/sqlalchemy/engine/base.py", line 1477, in _execute_ddl
    ret = self._execute_context(
  File "/home/airflow/.local/lib/python3.8/site-packages/sqlalchemy/engine/base.py", line 1953, in _execute_context
    self._handle_dbapi_exception(
  File "/home/airflow/.local/lib/python3.8/site-packages/sqlalchemy/engine/base.py", line 2134, in _handle_dbapi_exception
    util.raise_(
  File "/home/airflow/.local/lib/python3.8/site-packages/sqlalchemy/util/compat.py", line 211, in raise_
    raise exception
  File "/home/airflow/.local/lib/python3.8/site-packages/sqlalchemy/engine/base.py", line 1910, in _execute_context
    self.dialect.do_execute(
  File "/home/airflow/.local/lib/python3.8/site-packages/sqlalchemy/engine/default.py", line 736, in do_execute
    cursor.execute(statement, parameters)
sqlalchemy.exc.IntegrityError: (psycopg2.errors.UniqueViolation) duplicate key value violates unique constraint "pg_type_typname_nsp_index"
DETAIL:  Key (typname, typnamespace)=(M4_green_taxis_11_2017, 2200) already exists.

[SQL: 
CREATE TABLE "M4_green_taxis_11_2017" (
	"Unnamed: 0_x" BIGINT, 
	lpep_pickup_datetime TEXT, 
	lpep_dropoff_datetime TEXT, 
	store_and_fwd_flag BIGINT, 
	rate_type BIGINT, 
	pu_location BIGINT, 
	do_location BIGINT, 
	passenger_count FLOAT(53), 
	trip_distance FLOAT(53), 
	fare_amount FLOAT(53), 
	extra FLOAT(53), 
	mta_tax FLOAT(53), 
	tip_amount FLOAT(53), 
	tolls_amount FLOAT(53), 
	ehail_fee FLOAT(53), 
	improvement_surcharge FLOAT(53), 
	total_amount FLOAT(53), 
	payment_type BIGINT, 
	drop_off_neighborhood TEXT, 
	pick_up_neighborhood TEXT, 
	weekend BOOLEAN, 
	week_number BIGINT, 
	date_range FLOAT(53), 
	"Creative Mobile Technologies, LLC" BOOLEAN, 
	"VeriFone Inc." BOOLEAN, 
	ordered_through_phone_or_app BIGINT, 
	"Unnamed: 0_y" BIGINT, 
	do_location_address TEXT, 
	"Unnamed: 0" BIGINT, 
	pu_location_address TEXT, 
	do_longitude FLOAT(53), 
	do_latitude FLOAT(53), 
	pu_longitude FLOAT(53), 
	pu_latitude FLOAT(53)
)

]
(Background on this error at: https://sqlalche.me/e/14/gkpj)
[2023-12-16T13:35:45.849+0000] {taskinstance.py:1400} INFO - Marking task as FAILED. dag_id=NYC_Taxi_data_pipeline, task_id=integration, execution_date=20231214T000000, start_date=20231216T133521, end_date=20231216T133545
[2023-12-16T13:35:45.863+0000] {standard_task_runner.py:104} ERROR - Failed to execute job 6 for task integration ((psycopg2.errors.UniqueViolation) duplicate key value violates unique constraint "pg_type_typname_nsp_index"
DETAIL:  Key (typname, typnamespace)=(M4_green_taxis_11_2017, 2200) already exists.

[SQL: 
CREATE TABLE "M4_green_taxis_11_2017" (
	"Unnamed: 0_x" BIGINT, 
	lpep_pickup_datetime TEXT, 
	lpep_dropoff_datetime TEXT, 
	store_and_fwd_flag BIGINT, 
	rate_type BIGINT, 
	pu_location BIGINT, 
	do_location BIGINT, 
	passenger_count FLOAT(53), 
	trip_distance FLOAT(53), 
	fare_amount FLOAT(53), 
	extra FLOAT(53), 
	mta_tax FLOAT(53), 
	tip_amount FLOAT(53), 
	tolls_amount FLOAT(53), 
	ehail_fee FLOAT(53), 
	improvement_surcharge FLOAT(53), 
	total_amount FLOAT(53), 
	payment_type BIGINT, 
	drop_off_neighborhood TEXT, 
	pick_up_neighborhood TEXT, 
	weekend BOOLEAN, 
	week_number BIGINT, 
	date_range FLOAT(53), 
	"Creative Mobile Technologies, LLC" BOOLEAN, 
	"VeriFone Inc." BOOLEAN, 
	ordered_through_phone_or_app BIGINT, 
	"Unnamed: 0_y" BIGINT, 
	do_location_address TEXT, 
	"Unnamed: 0" BIGINT, 
	pu_location_address TEXT, 
	do_longitude FLOAT(53), 
	do_latitude FLOAT(53), 
	pu_longitude FLOAT(53), 
	pu_latitude FLOAT(53)
)

]
(Background on this error at: https://sqlalche.me/e/14/gkpj); 329)
[2023-12-16T13:35:45.904+0000] {local_task_job_runner.py:228} INFO - Task exited with return code 1
[2023-12-16T13:35:45.925+0000] {taskinstance.py:2778} INFO - 0 downstream tasks scheduled from follow-on schedule check
[2023-12-16T14:22:34.730+0000] {taskinstance.py:1159} INFO - Dependencies all met for dep_context=non-requeueable deps ti=<TaskInstance: NYC_Taxi_data_pipeline.integration scheduled__2023-12-14T00:00:00+00:00 [queued]>
[2023-12-16T14:22:34.750+0000] {taskinstance.py:1159} INFO - Dependencies all met for dep_context=requeueable deps ti=<TaskInstance: NYC_Taxi_data_pipeline.integration scheduled__2023-12-14T00:00:00+00:00 [queued]>
[2023-12-16T14:22:34.751+0000] {taskinstance.py:1361} INFO - Starting attempt 1 of 1
[2023-12-16T14:22:34.763+0000] {taskinstance.py:1382} INFO - Executing <Task(PythonOperator): integration> on 2023-12-14 00:00:00+00:00
[2023-12-16T14:22:34.769+0000] {standard_task_runner.py:57} INFO - Started process 320 to run task
[2023-12-16T14:22:34.773+0000] {standard_task_runner.py:84} INFO - Running: ['***', 'tasks', 'run', 'NYC_Taxi_data_pipeline', 'integration', 'scheduled__2023-12-14T00:00:00+00:00', '--job-id', '6', '--raw', '--subdir', 'DAGS_FOLDER/taxi_etl.py', '--cfg-path', '/tmp/tmpjuulmtwx']
[2023-12-16T14:22:34.775+0000] {standard_task_runner.py:85} INFO - Job 6: Subtask integration
[2023-12-16T14:22:34.820+0000] {task_command.py:416} INFO - Running <TaskInstance: NYC_Taxi_data_pipeline.integration scheduled__2023-12-14T00:00:00+00:00 [running]> on host 6abb98cbcbb2
[2023-12-16T14:22:34.893+0000] {taskinstance.py:1662} INFO - Exporting env vars: AIRFLOW_CTX_DAG_OWNER='islam' AIRFLOW_CTX_DAG_ID='NYC_Taxi_data_pipeline' AIRFLOW_CTX_TASK_ID='integration' AIRFLOW_CTX_EXECUTION_DATE='2023-12-14T00:00:00+00:00' AIRFLOW_CTX_TRY_NUMBER='1' AIRFLOW_CTX_DAG_RUN_ID='scheduled__2023-12-14T00:00:00+00:00'
[2023-12-16T14:22:38.698+0000] {logging_mixin.py:154} INFO - Database connect successfully
[2023-12-16T14:22:57.339+0000] {taskinstance.py:1937} ERROR - Task failed with exception
Traceback (most recent call last):
  File "/home/airflow/.local/lib/python3.8/site-packages/sqlalchemy/engine/base.py", line 1910, in _execute_context
    self.dialect.do_execute(
  File "/home/airflow/.local/lib/python3.8/site-packages/sqlalchemy/engine/default.py", line 736, in do_execute
    cursor.execute(statement, parameters)
psycopg2.errors.UniqueViolation: duplicate key value violates unique constraint "pg_type_typname_nsp_index"
DETAIL:  Key (typname, typnamespace)=(M4_green_taxis_11_2017, 2200) already exists.


The above exception was the direct cause of the following exception:

Traceback (most recent call last):
  File "/home/airflow/.local/lib/python3.8/site-packages/airflow/operators/python.py", line 192, in execute
    return_value = self.execute_callable()
  File "/home/airflow/.local/lib/python3.8/site-packages/airflow/operators/python.py", line 209, in execute_callable
    return self.python_callable(*self.op_args, **self.op_kwargs)
  File "/opt/airflow/dags/tasks.py", line 127, in integrate_and_load
    upload_csv(df_with_gps, "M4_green_taxis_11_2017", con)
  File "/opt/airflow/dags/utilities.py", line 40, in upload_csv
    df.to_sql(table_name, con = engine, if_exists='fail', index=False)
  File "/home/airflow/.local/lib/python3.8/site-packages/pandas/core/generic.py", line 2878, in to_sql
    return sql.to_sql(
  File "/home/airflow/.local/lib/python3.8/site-packages/pandas/io/sql.py", line 769, in to_sql
    return pandas_sql.to_sql(
  File "/home/airflow/.local/lib/python3.8/site-packages/pandas/io/sql.py", line 1910, in to_sql
    table = self.prep_table(
  File "/home/airflow/.local/lib/python3.8/site-packages/pandas/io/sql.py", line 1814, in prep_table
    table.create()
  File "/home/airflow/.local/lib/python3.8/site-packages/pandas/io/sql.py", line 914, in create
    self._execute_create()
  File "/home/airflow/.local/lib/python3.8/site-packages/pandas/io/sql.py", line 900, in _execute_create
    self.table.create(bind=self.pd_sql.con)
  File "/home/airflow/.local/lib/python3.8/site-packages/sqlalchemy/sql/schema.py", line 962, in create
    bind._run_ddl_visitor(ddl.SchemaGenerator, self, checkfirst=checkfirst)
  File "/home/airflow/.local/lib/python3.8/site-packages/sqlalchemy/engine/base.py", line 2221, in _run_ddl_visitor
    visitorcallable(self.dialect, self, **kwargs).traverse_single(element)
  File "/home/airflow/.local/lib/python3.8/site-packages/sqlalchemy/sql/visitors.py", line 524, in traverse_single
    return meth(obj, **kw)
  File "/home/airflow/.local/lib/python3.8/site-packages/sqlalchemy/sql/ddl.py", line 899, in visit_table
    self.connection.execute(
  File "/home/airflow/.local/lib/python3.8/site-packages/sqlalchemy/engine/base.py", line 1385, in execute
    return meth(self, multiparams, params, _EMPTY_EXECUTION_OPTS)
  File "/home/airflow/.local/lib/python3.8/site-packages/sqlalchemy/sql/ddl.py", line 80, in _execute_on_connection
    return connection._execute_ddl(
  File "/home/airflow/.local/lib/python3.8/site-packages/sqlalchemy/engine/base.py", line 1477, in _execute_ddl
    ret = self._execute_context(
  File "/home/airflow/.local/lib/python3.8/site-packages/sqlalchemy/engine/base.py", line 1953, in _execute_context
    self._handle_dbapi_exception(
  File "/home/airflow/.local/lib/python3.8/site-packages/sqlalchemy/engine/base.py", line 2134, in _handle_dbapi_exception
    util.raise_(
  File "/home/airflow/.local/lib/python3.8/site-packages/sqlalchemy/util/compat.py", line 211, in raise_
    raise exception
  File "/home/airflow/.local/lib/python3.8/site-packages/sqlalchemy/engine/base.py", line 1910, in _execute_context
    self.dialect.do_execute(
  File "/home/airflow/.local/lib/python3.8/site-packages/sqlalchemy/engine/default.py", line 736, in do_execute
    cursor.execute(statement, parameters)
sqlalchemy.exc.IntegrityError: (psycopg2.errors.UniqueViolation) duplicate key value violates unique constraint "pg_type_typname_nsp_index"
DETAIL:  Key (typname, typnamespace)=(M4_green_taxis_11_2017, 2200) already exists.

[SQL: 
CREATE TABLE "M4_green_taxis_11_2017" (
	"Unnamed: 0_x" BIGINT, 
	lpep_pickup_datetime TEXT, 
	lpep_dropoff_datetime TEXT, 
	store_and_fwd_flag BIGINT, 
	rate_type BIGINT, 
	pu_location BIGINT, 
	do_location BIGINT, 
	passenger_count FLOAT(53), 
	trip_distance FLOAT(53), 
	fare_amount FLOAT(53), 
	extra FLOAT(53), 
	mta_tax FLOAT(53), 
	tip_amount FLOAT(53), 
	tolls_amount FLOAT(53), 
	ehail_fee FLOAT(53), 
	improvement_surcharge FLOAT(53), 
	total_amount FLOAT(53), 
	payment_type BIGINT, 
	drop_off_neighborhood TEXT, 
	pick_up_neighborhood TEXT, 
	weekend BOOLEAN, 
	week_number BIGINT, 
	date_range FLOAT(53), 
	"Creative Mobile Technologies, LLC" BOOLEAN, 
	"VeriFone Inc." BOOLEAN, 
	ordered_through_phone_or_app BIGINT, 
	"Unnamed: 0_y" BIGINT, 
	do_location_address TEXT, 
	"Unnamed: 0" BIGINT, 
	pu_location_address TEXT, 
	do_longitude FLOAT(53), 
	do_latitude FLOAT(53), 
	pu_longitude FLOAT(53), 
	pu_latitude FLOAT(53)
)

]
(Background on this error at: https://sqlalche.me/e/14/gkpj)
[2023-12-16T14:22:57.463+0000] {taskinstance.py:1400} INFO - Marking task as FAILED. dag_id=NYC_Taxi_data_pipeline, task_id=integration, execution_date=20231214T000000, start_date=20231216T142234, end_date=20231216T142257
[2023-12-16T14:22:57.474+0000] {standard_task_runner.py:104} ERROR - Failed to execute job 6 for task integration ((psycopg2.errors.UniqueViolation) duplicate key value violates unique constraint "pg_type_typname_nsp_index"
DETAIL:  Key (typname, typnamespace)=(M4_green_taxis_11_2017, 2200) already exists.

[SQL: 
CREATE TABLE "M4_green_taxis_11_2017" (
	"Unnamed: 0_x" BIGINT, 
	lpep_pickup_datetime TEXT, 
	lpep_dropoff_datetime TEXT, 
	store_and_fwd_flag BIGINT, 
	rate_type BIGINT, 
	pu_location BIGINT, 
	do_location BIGINT, 
	passenger_count FLOAT(53), 
	trip_distance FLOAT(53), 
	fare_amount FLOAT(53), 
	extra FLOAT(53), 
	mta_tax FLOAT(53), 
	tip_amount FLOAT(53), 
	tolls_amount FLOAT(53), 
	ehail_fee FLOAT(53), 
	improvement_surcharge FLOAT(53), 
	total_amount FLOAT(53), 
	payment_type BIGINT, 
	drop_off_neighborhood TEXT, 
	pick_up_neighborhood TEXT, 
	weekend BOOLEAN, 
	week_number BIGINT, 
	date_range FLOAT(53), 
	"Creative Mobile Technologies, LLC" BOOLEAN, 
	"VeriFone Inc." BOOLEAN, 
	ordered_through_phone_or_app BIGINT, 
	"Unnamed: 0_y" BIGINT, 
	do_location_address TEXT, 
	"Unnamed: 0" BIGINT, 
	pu_location_address TEXT, 
	do_longitude FLOAT(53), 
	do_latitude FLOAT(53), 
	pu_longitude FLOAT(53), 
	pu_latitude FLOAT(53)
)

]
(Background on this error at: https://sqlalche.me/e/14/gkpj); 320)
[2023-12-16T14:22:57.497+0000] {local_task_job_runner.py:228} INFO - Task exited with return code 1
[2023-12-16T14:22:57.512+0000] {taskinstance.py:2778} INFO - 0 downstream tasks scheduled from follow-on schedule check
[2023-12-16T18:10:33.484+0000] {taskinstance.py:1159} INFO - Dependencies all met for dep_context=non-requeueable deps ti=<TaskInstance: NYC_Taxi_data_pipeline.integration scheduled__2023-12-14T00:00:00+00:00 [queued]>
[2023-12-16T18:10:33.587+0000] {taskinstance.py:1159} INFO - Dependencies all met for dep_context=requeueable deps ti=<TaskInstance: NYC_Taxi_data_pipeline.integration scheduled__2023-12-14T00:00:00+00:00 [queued]>
[2023-12-16T18:10:33.588+0000] {taskinstance.py:1361} INFO - Starting attempt 1 of 1
[2023-12-16T18:10:33.603+0000] {taskinstance.py:1382} INFO - Executing <Task(PythonOperator): integration> on 2023-12-14 00:00:00+00:00
[2023-12-16T18:10:33.623+0000] {standard_task_runner.py:57} INFO - Started process 395 to run task
[2023-12-16T18:10:33.626+0000] {standard_task_runner.py:84} INFO - Running: ['***', 'tasks', 'run', 'NYC_Taxi_data_pipeline', 'integration', 'scheduled__2023-12-14T00:00:00+00:00', '--job-id', '6', '--raw', '--subdir', 'DAGS_FOLDER/taxi_etl.py', '--cfg-path', '/tmp/tmp0hzgcsn0']
[2023-12-16T18:10:33.629+0000] {standard_task_runner.py:85} INFO - Job 6: Subtask integration
[2023-12-16T18:10:33.677+0000] {task_command.py:416} INFO - Running <TaskInstance: NYC_Taxi_data_pipeline.integration scheduled__2023-12-14T00:00:00+00:00 [running]> on host 1956fcd736af
[2023-12-16T18:10:33.783+0000] {taskinstance.py:1662} INFO - Exporting env vars: AIRFLOW_CTX_DAG_OWNER='islam' AIRFLOW_CTX_DAG_ID='NYC_Taxi_data_pipeline' AIRFLOW_CTX_TASK_ID='integration' AIRFLOW_CTX_EXECUTION_DATE='2023-12-14T00:00:00+00:00' AIRFLOW_CTX_TRY_NUMBER='1' AIRFLOW_CTX_DAG_RUN_ID='scheduled__2023-12-14T00:00:00+00:00'
[2023-12-16T18:10:37.084+0000] {logging_mixin.py:154} INFO - Database connect successfully
[2023-12-16T18:10:57.270+0000] {taskinstance.py:1937} ERROR - Task failed with exception
Traceback (most recent call last):
  File "/home/airflow/.local/lib/python3.8/site-packages/sqlalchemy/engine/base.py", line 1910, in _execute_context
    self.dialect.do_execute(
  File "/home/airflow/.local/lib/python3.8/site-packages/sqlalchemy/engine/default.py", line 736, in do_execute
    cursor.execute(statement, parameters)
psycopg2.errors.UniqueViolation: duplicate key value violates unique constraint "pg_type_typname_nsp_index"
DETAIL:  Key (typname, typnamespace)=(M4_green_taxis_11_2017, 2200) already exists.


The above exception was the direct cause of the following exception:

Traceback (most recent call last):
  File "/home/airflow/.local/lib/python3.8/site-packages/airflow/operators/python.py", line 192, in execute
    return_value = self.execute_callable()
  File "/home/airflow/.local/lib/python3.8/site-packages/airflow/operators/python.py", line 209, in execute_callable
    return self.python_callable(*self.op_args, **self.op_kwargs)
  File "/opt/airflow/dags/tasks.py", line 127, in integrate_and_load
    upload_csv(df_with_gps, "M4_green_taxis_11_2017", con)
  File "/opt/airflow/dags/utilities.py", line 40, in upload_csv
    df.to_sql(table_name, con = engine, if_exists='fail', index=False)
  File "/home/airflow/.local/lib/python3.8/site-packages/pandas/core/generic.py", line 2878, in to_sql
    return sql.to_sql(
  File "/home/airflow/.local/lib/python3.8/site-packages/pandas/io/sql.py", line 769, in to_sql
    return pandas_sql.to_sql(
  File "/home/airflow/.local/lib/python3.8/site-packages/pandas/io/sql.py", line 1910, in to_sql
    table = self.prep_table(
  File "/home/airflow/.local/lib/python3.8/site-packages/pandas/io/sql.py", line 1814, in prep_table
    table.create()
  File "/home/airflow/.local/lib/python3.8/site-packages/pandas/io/sql.py", line 914, in create
    self._execute_create()
  File "/home/airflow/.local/lib/python3.8/site-packages/pandas/io/sql.py", line 900, in _execute_create
    self.table.create(bind=self.pd_sql.con)
  File "/home/airflow/.local/lib/python3.8/site-packages/sqlalchemy/sql/schema.py", line 962, in create
    bind._run_ddl_visitor(ddl.SchemaGenerator, self, checkfirst=checkfirst)
  File "/home/airflow/.local/lib/python3.8/site-packages/sqlalchemy/engine/base.py", line 2221, in _run_ddl_visitor
    visitorcallable(self.dialect, self, **kwargs).traverse_single(element)
  File "/home/airflow/.local/lib/python3.8/site-packages/sqlalchemy/sql/visitors.py", line 524, in traverse_single
    return meth(obj, **kw)
  File "/home/airflow/.local/lib/python3.8/site-packages/sqlalchemy/sql/ddl.py", line 899, in visit_table
    self.connection.execute(
  File "/home/airflow/.local/lib/python3.8/site-packages/sqlalchemy/engine/base.py", line 1385, in execute
    return meth(self, multiparams, params, _EMPTY_EXECUTION_OPTS)
  File "/home/airflow/.local/lib/python3.8/site-packages/sqlalchemy/sql/ddl.py", line 80, in _execute_on_connection
    return connection._execute_ddl(
  File "/home/airflow/.local/lib/python3.8/site-packages/sqlalchemy/engine/base.py", line 1477, in _execute_ddl
    ret = self._execute_context(
  File "/home/airflow/.local/lib/python3.8/site-packages/sqlalchemy/engine/base.py", line 1953, in _execute_context
    self._handle_dbapi_exception(
  File "/home/airflow/.local/lib/python3.8/site-packages/sqlalchemy/engine/base.py", line 2134, in _handle_dbapi_exception
    util.raise_(
  File "/home/airflow/.local/lib/python3.8/site-packages/sqlalchemy/util/compat.py", line 211, in raise_
    raise exception
  File "/home/airflow/.local/lib/python3.8/site-packages/sqlalchemy/engine/base.py", line 1910, in _execute_context
    self.dialect.do_execute(
  File "/home/airflow/.local/lib/python3.8/site-packages/sqlalchemy/engine/default.py", line 736, in do_execute
    cursor.execute(statement, parameters)
sqlalchemy.exc.IntegrityError: (psycopg2.errors.UniqueViolation) duplicate key value violates unique constraint "pg_type_typname_nsp_index"
DETAIL:  Key (typname, typnamespace)=(M4_green_taxis_11_2017, 2200) already exists.

[SQL: 
CREATE TABLE "M4_green_taxis_11_2017" (
	"Unnamed: 0_x" BIGINT, 
	lpep_pickup_datetime TEXT, 
	lpep_dropoff_datetime TEXT, 
	store_and_fwd_flag BIGINT, 
	rate_type BIGINT, 
	pu_location BIGINT, 
	do_location BIGINT, 
	passenger_count FLOAT(53), 
	trip_distance FLOAT(53), 
	fare_amount FLOAT(53), 
	extra FLOAT(53), 
	mta_tax FLOAT(53), 
	tip_amount FLOAT(53), 
	tolls_amount FLOAT(53), 
	ehail_fee FLOAT(53), 
	improvement_surcharge FLOAT(53), 
	total_amount FLOAT(53), 
	payment_type BIGINT, 
	drop_off_neighborhood TEXT, 
	pick_up_neighborhood TEXT, 
	weekend BOOLEAN, 
	week_number BIGINT, 
	date_range FLOAT(53), 
	"Creative Mobile Technologies, LLC" BOOLEAN, 
	"VeriFone Inc." BOOLEAN, 
	ordered_through_phone_or_app BIGINT, 
	"Unnamed: 0_y" BIGINT, 
	do_location_address TEXT, 
	"Unnamed: 0" BIGINT, 
	pu_location_address TEXT, 
	do_longitude FLOAT(53), 
	do_latitude FLOAT(53), 
	pu_longitude FLOAT(53), 
	pu_latitude FLOAT(53)
)

]
(Background on this error at: https://sqlalche.me/e/14/gkpj)
[2023-12-16T18:10:57.424+0000] {taskinstance.py:1400} INFO - Marking task as FAILED. dag_id=NYC_Taxi_data_pipeline, task_id=integration, execution_date=20231214T000000, start_date=20231216T181033, end_date=20231216T181057
[2023-12-16T18:10:57.437+0000] {standard_task_runner.py:104} ERROR - Failed to execute job 6 for task integration ((psycopg2.errors.UniqueViolation) duplicate key value violates unique constraint "pg_type_typname_nsp_index"
DETAIL:  Key (typname, typnamespace)=(M4_green_taxis_11_2017, 2200) already exists.

[SQL: 
CREATE TABLE "M4_green_taxis_11_2017" (
	"Unnamed: 0_x" BIGINT, 
	lpep_pickup_datetime TEXT, 
	lpep_dropoff_datetime TEXT, 
	store_and_fwd_flag BIGINT, 
	rate_type BIGINT, 
	pu_location BIGINT, 
	do_location BIGINT, 
	passenger_count FLOAT(53), 
	trip_distance FLOAT(53), 
	fare_amount FLOAT(53), 
	extra FLOAT(53), 
	mta_tax FLOAT(53), 
	tip_amount FLOAT(53), 
	tolls_amount FLOAT(53), 
	ehail_fee FLOAT(53), 
	improvement_surcharge FLOAT(53), 
	total_amount FLOAT(53), 
	payment_type BIGINT, 
	drop_off_neighborhood TEXT, 
	pick_up_neighborhood TEXT, 
	weekend BOOLEAN, 
	week_number BIGINT, 
	date_range FLOAT(53), 
	"Creative Mobile Technologies, LLC" BOOLEAN, 
	"VeriFone Inc." BOOLEAN, 
	ordered_through_phone_or_app BIGINT, 
	"Unnamed: 0_y" BIGINT, 
	do_location_address TEXT, 
	"Unnamed: 0" BIGINT, 
	pu_location_address TEXT, 
	do_longitude FLOAT(53), 
	do_latitude FLOAT(53), 
	pu_longitude FLOAT(53), 
	pu_latitude FLOAT(53)
)

]
(Background on this error at: https://sqlalche.me/e/14/gkpj); 395)
[2023-12-16T18:10:57.474+0000] {local_task_job_runner.py:228} INFO - Task exited with return code 1
[2023-12-16T18:10:57.491+0000] {taskinstance.py:2778} INFO - 0 downstream tasks scheduled from follow-on schedule check
[2023-12-16T18:36:32.285+0000] {taskinstance.py:1159} INFO - Dependencies all met for dep_context=non-requeueable deps ti=<TaskInstance: NYC_Taxi_data_pipeline.integration scheduled__2023-12-14T00:00:00+00:00 [queued]>
[2023-12-16T18:36:32.389+0000] {taskinstance.py:1159} INFO - Dependencies all met for dep_context=requeueable deps ti=<TaskInstance: NYC_Taxi_data_pipeline.integration scheduled__2023-12-14T00:00:00+00:00 [queued]>
[2023-12-16T18:36:32.390+0000] {taskinstance.py:1361} INFO - Starting attempt 1 of 1
[2023-12-16T18:36:32.402+0000] {taskinstance.py:1382} INFO - Executing <Task(PythonOperator): integration> on 2023-12-14 00:00:00+00:00
[2023-12-16T18:36:32.408+0000] {standard_task_runner.py:57} INFO - Started process 329 to run task
[2023-12-16T18:36:32.411+0000] {standard_task_runner.py:84} INFO - Running: ['***', 'tasks', 'run', 'NYC_Taxi_data_pipeline', 'integration', 'scheduled__2023-12-14T00:00:00+00:00', '--job-id', '6', '--raw', '--subdir', 'DAGS_FOLDER/taxi_etl.py', '--cfg-path', '/tmp/tmpk2zde603']
[2023-12-16T18:36:32.414+0000] {standard_task_runner.py:85} INFO - Job 6: Subtask integration
[2023-12-16T18:36:32.458+0000] {task_command.py:416} INFO - Running <TaskInstance: NYC_Taxi_data_pipeline.integration scheduled__2023-12-14T00:00:00+00:00 [running]> on host 570873a10993
[2023-12-16T18:36:32.525+0000] {taskinstance.py:1662} INFO - Exporting env vars: AIRFLOW_CTX_DAG_OWNER='islam' AIRFLOW_CTX_DAG_ID='NYC_Taxi_data_pipeline' AIRFLOW_CTX_TASK_ID='integration' AIRFLOW_CTX_EXECUTION_DATE='2023-12-14T00:00:00+00:00' AIRFLOW_CTX_TRY_NUMBER='1' AIRFLOW_CTX_DAG_RUN_ID='scheduled__2023-12-14T00:00:00+00:00'
[2023-12-16T18:36:35.601+0000] {logging_mixin.py:154} INFO - Database connect successfully
[2023-12-16T18:36:56.799+0000] {taskinstance.py:1937} ERROR - Task failed with exception
Traceback (most recent call last):
  File "/home/airflow/.local/lib/python3.8/site-packages/sqlalchemy/engine/base.py", line 1910, in _execute_context
    self.dialect.do_execute(
  File "/home/airflow/.local/lib/python3.8/site-packages/sqlalchemy/engine/default.py", line 736, in do_execute
    cursor.execute(statement, parameters)
psycopg2.errors.UniqueViolation: duplicate key value violates unique constraint "pg_type_typname_nsp_index"
DETAIL:  Key (typname, typnamespace)=(M4_green_taxis_11_2017, 2200) already exists.


The above exception was the direct cause of the following exception:

Traceback (most recent call last):
  File "/home/airflow/.local/lib/python3.8/site-packages/airflow/operators/python.py", line 192, in execute
    return_value = self.execute_callable()
  File "/home/airflow/.local/lib/python3.8/site-packages/airflow/operators/python.py", line 209, in execute_callable
    return self.python_callable(*self.op_args, **self.op_kwargs)
  File "/opt/airflow/dags/tasks.py", line 127, in integrate_and_load
    upload_csv(df_with_gps, "M4_green_taxis_11_2017", con)
  File "/opt/airflow/dags/utilities.py", line 40, in upload_csv
    df.to_sql(table_name, con = engine, if_exists='fail', index=False)
  File "/home/airflow/.local/lib/python3.8/site-packages/pandas/core/generic.py", line 2878, in to_sql
    return sql.to_sql(
  File "/home/airflow/.local/lib/python3.8/site-packages/pandas/io/sql.py", line 769, in to_sql
    return pandas_sql.to_sql(
  File "/home/airflow/.local/lib/python3.8/site-packages/pandas/io/sql.py", line 1910, in to_sql
    table = self.prep_table(
  File "/home/airflow/.local/lib/python3.8/site-packages/pandas/io/sql.py", line 1814, in prep_table
    table.create()
  File "/home/airflow/.local/lib/python3.8/site-packages/pandas/io/sql.py", line 914, in create
    self._execute_create()
  File "/home/airflow/.local/lib/python3.8/site-packages/pandas/io/sql.py", line 900, in _execute_create
    self.table.create(bind=self.pd_sql.con)
  File "/home/airflow/.local/lib/python3.8/site-packages/sqlalchemy/sql/schema.py", line 962, in create
    bind._run_ddl_visitor(ddl.SchemaGenerator, self, checkfirst=checkfirst)
  File "/home/airflow/.local/lib/python3.8/site-packages/sqlalchemy/engine/base.py", line 2221, in _run_ddl_visitor
    visitorcallable(self.dialect, self, **kwargs).traverse_single(element)
  File "/home/airflow/.local/lib/python3.8/site-packages/sqlalchemy/sql/visitors.py", line 524, in traverse_single
    return meth(obj, **kw)
  File "/home/airflow/.local/lib/python3.8/site-packages/sqlalchemy/sql/ddl.py", line 899, in visit_table
    self.connection.execute(
  File "/home/airflow/.local/lib/python3.8/site-packages/sqlalchemy/engine/base.py", line 1385, in execute
    return meth(self, multiparams, params, _EMPTY_EXECUTION_OPTS)
  File "/home/airflow/.local/lib/python3.8/site-packages/sqlalchemy/sql/ddl.py", line 80, in _execute_on_connection
    return connection._execute_ddl(
  File "/home/airflow/.local/lib/python3.8/site-packages/sqlalchemy/engine/base.py", line 1477, in _execute_ddl
    ret = self._execute_context(
  File "/home/airflow/.local/lib/python3.8/site-packages/sqlalchemy/engine/base.py", line 1953, in _execute_context
    self._handle_dbapi_exception(
  File "/home/airflow/.local/lib/python3.8/site-packages/sqlalchemy/engine/base.py", line 2134, in _handle_dbapi_exception
    util.raise_(
  File "/home/airflow/.local/lib/python3.8/site-packages/sqlalchemy/util/compat.py", line 211, in raise_
    raise exception
  File "/home/airflow/.local/lib/python3.8/site-packages/sqlalchemy/engine/base.py", line 1910, in _execute_context
    self.dialect.do_execute(
  File "/home/airflow/.local/lib/python3.8/site-packages/sqlalchemy/engine/default.py", line 736, in do_execute
    cursor.execute(statement, parameters)
sqlalchemy.exc.IntegrityError: (psycopg2.errors.UniqueViolation) duplicate key value violates unique constraint "pg_type_typname_nsp_index"
DETAIL:  Key (typname, typnamespace)=(M4_green_taxis_11_2017, 2200) already exists.

[SQL: 
CREATE TABLE "M4_green_taxis_11_2017" (
	"Unnamed: 0_x" BIGINT, 
	lpep_pickup_datetime TEXT, 
	lpep_dropoff_datetime TEXT, 
	store_and_fwd_flag BIGINT, 
	rate_type BIGINT, 
	pu_location BIGINT, 
	do_location BIGINT, 
	passenger_count FLOAT(53), 
	trip_distance FLOAT(53), 
	fare_amount FLOAT(53), 
	extra FLOAT(53), 
	mta_tax FLOAT(53), 
	tip_amount FLOAT(53), 
	tolls_amount FLOAT(53), 
	ehail_fee FLOAT(53), 
	improvement_surcharge FLOAT(53), 
	total_amount FLOAT(53), 
	payment_type BIGINT, 
	drop_off_neighborhood TEXT, 
	pick_up_neighborhood TEXT, 
	weekend BOOLEAN, 
	week_number BIGINT, 
	date_range FLOAT(53), 
	"Creative Mobile Technologies, LLC" BOOLEAN, 
	"VeriFone Inc." BOOLEAN, 
	ordered_through_phone_or_app BIGINT, 
	"Unnamed: 0_y" BIGINT, 
	do_location_address TEXT, 
	"Unnamed: 0" BIGINT, 
	pu_location_address TEXT, 
	do_longitude FLOAT(53), 
	do_latitude FLOAT(53), 
	pu_longitude FLOAT(53), 
	pu_latitude FLOAT(53)
)

]
(Background on this error at: https://sqlalche.me/e/14/gkpj)
[2023-12-16T18:36:56.820+0000] {taskinstance.py:1400} INFO - Marking task as FAILED. dag_id=NYC_Taxi_data_pipeline, task_id=integration, execution_date=20231214T000000, start_date=20231216T183632, end_date=20231216T183656
[2023-12-16T18:36:56.834+0000] {standard_task_runner.py:104} ERROR - Failed to execute job 6 for task integration ((psycopg2.errors.UniqueViolation) duplicate key value violates unique constraint "pg_type_typname_nsp_index"
DETAIL:  Key (typname, typnamespace)=(M4_green_taxis_11_2017, 2200) already exists.

[SQL: 
CREATE TABLE "M4_green_taxis_11_2017" (
	"Unnamed: 0_x" BIGINT, 
	lpep_pickup_datetime TEXT, 
	lpep_dropoff_datetime TEXT, 
	store_and_fwd_flag BIGINT, 
	rate_type BIGINT, 
	pu_location BIGINT, 
	do_location BIGINT, 
	passenger_count FLOAT(53), 
	trip_distance FLOAT(53), 
	fare_amount FLOAT(53), 
	extra FLOAT(53), 
	mta_tax FLOAT(53), 
	tip_amount FLOAT(53), 
	tolls_amount FLOAT(53), 
	ehail_fee FLOAT(53), 
	improvement_surcharge FLOAT(53), 
	total_amount FLOAT(53), 
	payment_type BIGINT, 
	drop_off_neighborhood TEXT, 
	pick_up_neighborhood TEXT, 
	weekend BOOLEAN, 
	week_number BIGINT, 
	date_range FLOAT(53), 
	"Creative Mobile Technologies, LLC" BOOLEAN, 
	"VeriFone Inc." BOOLEAN, 
	ordered_through_phone_or_app BIGINT, 
	"Unnamed: 0_y" BIGINT, 
	do_location_address TEXT, 
	"Unnamed: 0" BIGINT, 
	pu_location_address TEXT, 
	do_longitude FLOAT(53), 
	do_latitude FLOAT(53), 
	pu_longitude FLOAT(53), 
	pu_latitude FLOAT(53)
)

]
(Background on this error at: https://sqlalche.me/e/14/gkpj); 329)
[2023-12-16T18:36:56.865+0000] {local_task_job_runner.py:228} INFO - Task exited with return code 1
[2023-12-16T18:36:56.883+0000] {taskinstance.py:2778} INFO - 0 downstream tasks scheduled from follow-on schedule check
[2023-12-16T18:42:11.200+0000] {taskinstance.py:1159} INFO - Dependencies all met for dep_context=non-requeueable deps ti=<TaskInstance: NYC_Taxi_data_pipeline.integration scheduled__2023-12-14T00:00:00+00:00 [queued]>
[2023-12-16T18:42:11.217+0000] {taskinstance.py:1159} INFO - Dependencies all met for dep_context=requeueable deps ti=<TaskInstance: NYC_Taxi_data_pipeline.integration scheduled__2023-12-14T00:00:00+00:00 [queued]>
[2023-12-16T18:42:11.218+0000] {taskinstance.py:1361} INFO - Starting attempt 1 of 1
[2023-12-16T18:42:11.236+0000] {taskinstance.py:1382} INFO - Executing <Task(PythonOperator): integration> on 2023-12-14 00:00:00+00:00
[2023-12-16T18:42:11.244+0000] {standard_task_runner.py:57} INFO - Started process 321 to run task
[2023-12-16T18:42:11.248+0000] {standard_task_runner.py:84} INFO - Running: ['***', 'tasks', 'run', 'NYC_Taxi_data_pipeline', 'integration', 'scheduled__2023-12-14T00:00:00+00:00', '--job-id', '7', '--raw', '--subdir', 'DAGS_FOLDER/taxi_etl.py', '--cfg-path', '/tmp/tmppd71i62x']
[2023-12-16T18:42:11.251+0000] {standard_task_runner.py:85} INFO - Job 7: Subtask integration
[2023-12-16T18:42:11.312+0000] {task_command.py:416} INFO - Running <TaskInstance: NYC_Taxi_data_pipeline.integration scheduled__2023-12-14T00:00:00+00:00 [running]> on host 40ff33ca59cb
[2023-12-16T18:42:11.397+0000] {taskinstance.py:1662} INFO - Exporting env vars: AIRFLOW_CTX_DAG_OWNER='islam' AIRFLOW_CTX_DAG_ID='NYC_Taxi_data_pipeline' AIRFLOW_CTX_TASK_ID='integration' AIRFLOW_CTX_EXECUTION_DATE='2023-12-14T00:00:00+00:00' AIRFLOW_CTX_TRY_NUMBER='1' AIRFLOW_CTX_DAG_RUN_ID='scheduled__2023-12-14T00:00:00+00:00'
[2023-12-16T18:42:13.005+0000] {logging_mixin.py:154} INFO - Database connect successfully
[2023-12-16T18:42:33.726+0000] {taskinstance.py:1937} ERROR - Task failed with exception
Traceback (most recent call last):
  File "/home/airflow/.local/lib/python3.8/site-packages/sqlalchemy/engine/base.py", line 1910, in _execute_context
    self.dialect.do_execute(
  File "/home/airflow/.local/lib/python3.8/site-packages/sqlalchemy/engine/default.py", line 736, in do_execute
    cursor.execute(statement, parameters)
psycopg2.errors.UniqueViolation: duplicate key value violates unique constraint "pg_type_typname_nsp_index"
DETAIL:  Key (typname, typnamespace)=(M4_green_taxis_11_2017, 2200) already exists.


The above exception was the direct cause of the following exception:

Traceback (most recent call last):
  File "/home/airflow/.local/lib/python3.8/site-packages/airflow/operators/python.py", line 192, in execute
    return_value = self.execute_callable()
  File "/home/airflow/.local/lib/python3.8/site-packages/airflow/operators/python.py", line 209, in execute_callable
    return self.python_callable(*self.op_args, **self.op_kwargs)
  File "/opt/airflow/dags/tasks.py", line 127, in integrate_and_load
    upload_csv(df_with_gps, "M4_green_taxis_11_2017", con)
  File "/opt/airflow/dags/utilities.py", line 40, in upload_csv
    df.to_sql(table_name, con = engine, if_exists='fail', index=False)
  File "/home/airflow/.local/lib/python3.8/site-packages/pandas/core/generic.py", line 2878, in to_sql
    return sql.to_sql(
  File "/home/airflow/.local/lib/python3.8/site-packages/pandas/io/sql.py", line 769, in to_sql
    return pandas_sql.to_sql(
  File "/home/airflow/.local/lib/python3.8/site-packages/pandas/io/sql.py", line 1910, in to_sql
    table = self.prep_table(
  File "/home/airflow/.local/lib/python3.8/site-packages/pandas/io/sql.py", line 1814, in prep_table
    table.create()
  File "/home/airflow/.local/lib/python3.8/site-packages/pandas/io/sql.py", line 914, in create
    self._execute_create()
  File "/home/airflow/.local/lib/python3.8/site-packages/pandas/io/sql.py", line 900, in _execute_create
    self.table.create(bind=self.pd_sql.con)
  File "/home/airflow/.local/lib/python3.8/site-packages/sqlalchemy/sql/schema.py", line 962, in create
    bind._run_ddl_visitor(ddl.SchemaGenerator, self, checkfirst=checkfirst)
  File "/home/airflow/.local/lib/python3.8/site-packages/sqlalchemy/engine/base.py", line 2221, in _run_ddl_visitor
    visitorcallable(self.dialect, self, **kwargs).traverse_single(element)
  File "/home/airflow/.local/lib/python3.8/site-packages/sqlalchemy/sql/visitors.py", line 524, in traverse_single
    return meth(obj, **kw)
  File "/home/airflow/.local/lib/python3.8/site-packages/sqlalchemy/sql/ddl.py", line 899, in visit_table
    self.connection.execute(
  File "/home/airflow/.local/lib/python3.8/site-packages/sqlalchemy/engine/base.py", line 1385, in execute
    return meth(self, multiparams, params, _EMPTY_EXECUTION_OPTS)
  File "/home/airflow/.local/lib/python3.8/site-packages/sqlalchemy/sql/ddl.py", line 80, in _execute_on_connection
    return connection._execute_ddl(
  File "/home/airflow/.local/lib/python3.8/site-packages/sqlalchemy/engine/base.py", line 1477, in _execute_ddl
    ret = self._execute_context(
  File "/home/airflow/.local/lib/python3.8/site-packages/sqlalchemy/engine/base.py", line 1953, in _execute_context
    self._handle_dbapi_exception(
  File "/home/airflow/.local/lib/python3.8/site-packages/sqlalchemy/engine/base.py", line 2134, in _handle_dbapi_exception
    util.raise_(
  File "/home/airflow/.local/lib/python3.8/site-packages/sqlalchemy/util/compat.py", line 211, in raise_
    raise exception
  File "/home/airflow/.local/lib/python3.8/site-packages/sqlalchemy/engine/base.py", line 1910, in _execute_context
    self.dialect.do_execute(
  File "/home/airflow/.local/lib/python3.8/site-packages/sqlalchemy/engine/default.py", line 736, in do_execute
    cursor.execute(statement, parameters)
sqlalchemy.exc.IntegrityError: (psycopg2.errors.UniqueViolation) duplicate key value violates unique constraint "pg_type_typname_nsp_index"
DETAIL:  Key (typname, typnamespace)=(M4_green_taxis_11_2017, 2200) already exists.

[SQL: 
CREATE TABLE "M4_green_taxis_11_2017" (
	"Unnamed: 0_x" BIGINT, 
	lpep_pickup_datetime TEXT, 
	lpep_dropoff_datetime TEXT, 
	store_and_fwd_flag BIGINT, 
	rate_type BIGINT, 
	pu_location BIGINT, 
	do_location BIGINT, 
	passenger_count FLOAT(53), 
	trip_distance FLOAT(53), 
	fare_amount FLOAT(53), 
	extra FLOAT(53), 
	mta_tax FLOAT(53), 
	tip_amount FLOAT(53), 
	tolls_amount FLOAT(53), 
	ehail_fee FLOAT(53), 
	improvement_surcharge FLOAT(53), 
	total_amount FLOAT(53), 
	payment_type BIGINT, 
	drop_off_neighborhood TEXT, 
	pick_up_neighborhood TEXT, 
	weekend BOOLEAN, 
	week_number BIGINT, 
	date_range FLOAT(53), 
	"Creative Mobile Technologies, LLC" BOOLEAN, 
	"VeriFone Inc." BOOLEAN, 
	ordered_through_phone_or_app BIGINT, 
	"Unnamed: 0_y" BIGINT, 
	do_location_address TEXT, 
	"Unnamed: 0" BIGINT, 
	pu_location_address TEXT, 
	do_longitude FLOAT(53), 
	do_latitude FLOAT(53), 
	pu_longitude FLOAT(53), 
	pu_latitude FLOAT(53)
)

]
(Background on this error at: https://sqlalche.me/e/14/gkpj)
[2023-12-16T18:42:33.750+0000] {taskinstance.py:1400} INFO - Marking task as FAILED. dag_id=NYC_Taxi_data_pipeline, task_id=integration, execution_date=20231214T000000, start_date=20231216T184211, end_date=20231216T184233
[2023-12-16T18:42:33.767+0000] {standard_task_runner.py:104} ERROR - Failed to execute job 7 for task integration ((psycopg2.errors.UniqueViolation) duplicate key value violates unique constraint "pg_type_typname_nsp_index"
DETAIL:  Key (typname, typnamespace)=(M4_green_taxis_11_2017, 2200) already exists.

[SQL: 
CREATE TABLE "M4_green_taxis_11_2017" (
	"Unnamed: 0_x" BIGINT, 
	lpep_pickup_datetime TEXT, 
	lpep_dropoff_datetime TEXT, 
	store_and_fwd_flag BIGINT, 
	rate_type BIGINT, 
	pu_location BIGINT, 
	do_location BIGINT, 
	passenger_count FLOAT(53), 
	trip_distance FLOAT(53), 
	fare_amount FLOAT(53), 
	extra FLOAT(53), 
	mta_tax FLOAT(53), 
	tip_amount FLOAT(53), 
	tolls_amount FLOAT(53), 
	ehail_fee FLOAT(53), 
	improvement_surcharge FLOAT(53), 
	total_amount FLOAT(53), 
	payment_type BIGINT, 
	drop_off_neighborhood TEXT, 
	pick_up_neighborhood TEXT, 
	weekend BOOLEAN, 
	week_number BIGINT, 
	date_range FLOAT(53), 
	"Creative Mobile Technologies, LLC" BOOLEAN, 
	"VeriFone Inc." BOOLEAN, 
	ordered_through_phone_or_app BIGINT, 
	"Unnamed: 0_y" BIGINT, 
	do_location_address TEXT, 
	"Unnamed: 0" BIGINT, 
	pu_location_address TEXT, 
	do_longitude FLOAT(53), 
	do_latitude FLOAT(53), 
	pu_longitude FLOAT(53), 
	pu_latitude FLOAT(53)
)

]
(Background on this error at: https://sqlalche.me/e/14/gkpj); 321)
[2023-12-16T18:42:33.785+0000] {local_task_job_runner.py:228} INFO - Task exited with return code 1
[2023-12-16T18:42:33.806+0000] {taskinstance.py:2778} INFO - 0 downstream tasks scheduled from follow-on schedule check
